{"version":1,"defects":{"Tests\\Unit\\RouterTest::it_throws_unknown_uri_esception with data set #2":4,"Error":4,"Tests\\Unit\\RouterTest::it_throws_unknown_uri_esception with data set #0":4,"Tests\\Unit\\RouterTest::it_throws_unknown_uri_esception with data set #1":4,"Tests\\Unit\\RouterTest::it_throws_unknown_uri_esception with data set #3":4,"Tests\\Unit\\RouterTest::it_test_from_a_closure":4},"times":{"Tests\\Unit\\RouterTest::it_registers_a_route":0.079,"Tests\\Unit\\RouterTest::it_throws_unknown_uri_esception with data set #0":0.103,"Tests\\Unit\\RouterTest::it_throws_unknown_uri_esception with data set #1":0,"Tests\\Unit\\RouterTest::it_throws_unknown_uri_esception with data set #2":0,"Tests\\Unit\\RouterTest::it_throws_unknown_uri_esception with data set #3":0,"Error":0.061,"Tests\\Unit\\RouterTest::it_test_from_a_closure":0.096,"Tests\\Unit\\RouterTest::it_tests_resolution_a_route":0.088}}